Workbook

Sheet UIO
A1: Model | B1: 2013 | C1: 2014 | D1: 2015 | E1: 2016 | F1: 2017 | G1: 2018 | H1: 2019 | I1: 2020 | J1: 2021 | K1: 2025 | L1: 2026* | M1: UIO
A2: FZ16 | B2: 187 | C2: 925 | D2: 602 | E2: - | F2: - | G2: - | H2: - | I2: - | J2: - | K2: - | L2: - | M2: =SUM(B2:L2) -> 1714
A3: FZ16S | B3: 196 | C3: 1028 | D3: 623 | E3: - | F3: - | G3: - | H3: - | I3: - | J3: - | K3: - | L3: - | M3: =SUM(B3:L3) -> 1847
A4: FZ16ST(FAZER) | B4: 29 | C4: 125 | D4: 78 | E4: - | F4: - | G4: - | H4: - | I4: - | J4: - | K4: - | L4: - | M4: =SUM(B4:L4) -> 232
A5: FZ合計 | B5: 412 | C5: 2078 | D5: 1303 | E5: - | F5: - | G5: - | H5: - | I5: - | J5: - | K5: - | L5: - | M5: =SUM(B5:L5) -> 3793
A6: SZ 16 | B6: - | C6: - | D6: - | E6: - | F6: - | G6: - | H6: - | I6: - | J6: - | K6: - | L6: - | M6: =SUM(B6:L6) -> 0
A7: SZ X | B7: 15 | C7: 129 | D7: - | E7: - | F7: - | G7: - | H7: - | I7: - | J7: - | K7: - | L7: - | M7: =SUM(B7:L7) -> 144
A8: SZ R | B8: 34 | C8: 42 | D8: - | E8: - | F8: - | G8: - | H8: - | I8: - | J8: - | K8: - | L8: - | M8: =SUM(B8:L8) -> 76
A9: XTZ 125E | B9: - | C9: - | D9: - | E9: - | F9: - | G9: - | H9: - | I9: - | J9: - | K9: - | L9: - | M9: =SUM(B9:L9) -> 0
A10: YZ 125 | B10: - | C10: - | D10: - | E10: - | F10: - | G10: - | H10: - | I10: - | J10: - | K10: - | L10: - | M10: =SUM(B10:L10) -> 0
A11: YBR110 | B11: - | C11: - | D11: 20 | E11: - | F11: - | G11: - | H11: - | I11: - | J11: - | K11: - | L11: - | M11: =SUM(B11:L11) -> 20
A12: YBR125 | B12: - | C12: - | D12: - | E12: - | F12: - | G12: - | H12: - | I12: - | J12: - | K12: - | L12: - | M12: =SUM(B12:L12) -> 0
A13: RAY Original | B13: 348 | C13: 1316 | D13: 606 | E13: 13 | F13: - | G13: - | H13: - | I13: - | J13: - | K13: - | L13: - | M13: =SUM(B13:L13) -> 2283
A14: YZ 250 | B14: - | C14: - | D14: - | E14: - | F14: - | G14: - | H14: - | I14: - | J14: - | K14: - | L14: - | M14: =SUM(B14:L14) -> 0
A15: YZF-R15 | B15: - | C15: - | D15: 13 | E15: 48 | F15: 55 | G15: 101 | H15: 784 | I15: 566 | J15: 1 | K15: 832 | L15: 80 | M15: =SUM(B15:L15) -> 2480
A16: XC115F | B16: - | C16: 22 | D16: 624 | E16: 514 | F16: - | G16: - | H16: - | I16: - | J16: - | K16: - | L16: - | M16: =SUM(B16:L16) -> 1160
A17: FZN150 | B17: - | C17: - | D17: 861 | E17: 2257 | F17: - | G17: - | H17: - | I17: - | J17: - | K17: - | L17: - | M17: =SUM(B17:L17) -> 3118
A18: FZN150D | B18: - | C18: - | D18: 1577 | E18: 4317 | F18: - | G18: - | H18: - | I18: - | J18: - | K18: - | L18: - | M18: =SUM(B18:L18) -> 5894
A19: FZH150(FAZER) | B19: - | C19: - | D19: 164 | E19: 474 | F19: - | G19: - | H19: - | I19: - | J19: - | K19: - | L19: - | M19: =SUM(B19:L19) -> 638
A20: YC125-5 | B20: - | C20: - | D20: 46 | E20: 622 | F20: - | G20: - | H20: - | I20: - | J20: - | K20: - | L20: - | M20: =SUM(B20:L20) -> 668
A21: XC115B | B21: - | C21: - | D21: 1586 | E21: 1950 | F21: - | G21: - | H21: - | I21: - | J21: - | K21: - | L21: - | M21: =SUM(B21:L21) -> 3536
A22: FASCINO | B22: - | C22: - | D22: - | E22: 421 | F22: - | G22: - | H22: - | I22: - | J22: - | K22: - | L22: - | M22: =SUM(B22:L22) -> 421
A23: RAY | B23: - | C23: - | D23: - | E23: - | F23: - | G23: - | H23: - | I23: - | J23: - | K23: - | L23: - | M23: =SUM(B23:L23) -> 0
A24: RAY ZR(Drum) | B24: - | C24: - | D24: - | E24: 3359 | F24: - | G24: - | H24: - | I24: - | J24: - | K24: - | L24: - | M24: =SUM(B24:L24) -> 3359
A25: RAY ZR(Disk) | B25: - | C25: - | D25: - | E25: 304 | F25: - | G25: - | H25: - | I25: - | J25: - | K25: - | L25: - | M25: =SUM(B25:L25) -> 304
A26: XJ900PCZ6 | B26: - | C26: - | D26: - | E26: - | F26: - | G26: - | H26: - | I26: - | J26: - | K26: - | L26: - | M26: =SUM(B26:L26) -> 0
A27: FZN150 FZ ver.2 | B27: - | C27: - | D27: - | E27: - | F27: 2164 | G27: 3902 | H27: 3691 | I27: 2053 | J27: 1 | K27: - | L27: - | M27: =SUM(B27:L27) -> 11811
A28: FZN150D FZS ver.2 | B28: - | C28: - | D28: - | E28: - | F28: 5549 | G28: 6249 | H28: 2163 | I28: - | J28: - | K28: - | L28: - | M28: =SUM(B28:L28) -> 13961
A29: FZN250 | B29: - | C29: - | D29: - | E29: - | F29: 22 | G29: 91 | H29: 23 | I29: 30 | J29: 1 | K29: - | L29: - | M29: =SUM(B29:L29) -> 167
A30: FZH150 FAZER ver.2 | B30: - | C30: - | D30: - | E30: - | F30: 635 | G30: 709 | H30: 472 | I30: 265 | J30: 4 | K30: - | L30: - | M30: =SUM(B30:L30) -> 2085
A31: YC125-5 SALUTO DISK | B31: - | C31: - | D31: - | E31: - | F31: 401 | G31: 302 | H31: 220 | I31: 142 | J31: 11 | K31: - | L31: - | M31: =SUM(B31:L31) -> 1076
A32: XC115B RAY Z | B32: - | C32: - | D32: - | E32: - | F32: 17 | G32: - | H32: 42 | I32: - | J32: - | K32: - | L32: - | M32: =SUM(B32:L32) -> 59
A33: RAY Z (NEW) | B33: - | C33: - | D33: - | E33: - | F33: 71 | G33: 898 | H33: 527 | I33: 261 | J33: - | K33: - | L33: - | M33: =SUM(B33:L33) -> 1757
A34: XC115C FASCINO | B34: - | C34: - | D34: - | E34: - | F34: 247 | G34: 436 | H34: 464 | I34: 363 | J34: 1 | K34: - | L34: - | M34: =SUM(B34:L34) -> 1511
A35: XC115F ALPHA | B35: - | C35: - | D35: - | E35: - | F35: 134 | G35: 60 | H35: 21 | J35: 1 | K35: - | L35: - | M35: =SUM(B35:L35) -> 216
A36: XC115B RAY ZR(Drum) | B36: - | C36: - | D36: - | E36: - | F36: 10244 | G36: 8188 | H36: 4577 | I36: 2237 | J36: 4 | K36: - | L36: - | M36: =SUM(B36:L36) -> 25250
A37: XC115BD RAY ZR(Disk) | B37: - | C37: - | D37: - | E37: - | F37: 4303 | G37: 10082 | H37: 7302 | I37: 3544 | J37: 3 | K37: - | L37: - | M37: =SUM(B37:L37) -> 25234
A38: R3 | B38: - | C38: - | D38: - | E38: - | F38: - | G38: - | H38: - | I38: - | J38: - | K38: - | L38: - | M38: =SUM(B38:L38) -> 0
A39: FZN150D(Rear Disc.) | B39: - | C39: - | D39: - | E39: - | F39: - | G39: 753 | H39: 1645 | I39: - | J39: 1 | K39: - | L39: - | M39: =SUM(B39:L39) -> 2399
A40: XC115F ALPHA DISC | B40: - | C40: - | D40: - | E40: - | F40: - | G40: 322 | H40: 224 | I40: 137 | J40: 1 | K40: - | L40: - | M40: =SUM(B40:L40) -> 684
...

Sheet SU
A1: Model | B1: 2013 | C1: 2014 | D1: 2015 | E1: 2016 | F1: 2017 | G1: 2018 | H1: 2019 | I1: 2020 | J1: 2021 | K1: 2025 | L1: 2026* | M1: Total Sales Units
A2: FZ16 | B2: =_xlfn.XLOOKUP(A2,'2013'!A:A,'2013'!N:N,"-") -> 935 | C2: =_xlfn.XLOOKUP(A2,'2014'!A:A,'2014'!N:N,"-") -> 2313 | D2: =_xlfn.XLOOKUP(A2,'2015'!A:A,'2015'!N:N,"-") -> 1505 | E2: =_xlfn.XLOOKUP(A2,'2016'!A:A,'2016'!N:N,"-") -> 4 | F2: =_xlfn.XLOOKUP(A2,'2017'!A:A,'2017'!N:N,"-") -> 1 | G2: =_xlfn.XLOOKUP(A2,'2018'!A:A,'2018'!N:N,"-") -> - | H2: =_xlfn.XLOOKUP(A2,'2019'!A:A,'2019'!N:N,"-") -> - | I2: =_xlfn.XLOOKUP(A2,'2020'!A:A,'2020'!N:N,"-") -> - | J2: =_xlfn.XLOOKUP(A2,'2021'!A:A,'2021'!N:N,"-") -> - | K2: =_xlfn.XLOOKUP(A2,'2025'!A:A,'2025'!N:N,"-") -> - | L2: =_xlfn.XLOOKUP(A2,'2026'!A:A,'2026'!N:N,"-") -> - | M2: =SUM(B2:L2) -> 4758
A3: FZ16S | B3: =_xlfn.XLOOKUP(A3,'2013'!A:A,'2013'!N:N,"-") -> 982 | C3: =_xlfn.XLOOKUP(A3,'2014'!A:A,'2014'!N:N,"-") -> 2569 | D3: =_xlfn.XLOOKUP(A3,'2015'!A:A,'2015'!N:N,"-") -> 1557 | E3: =_xlfn.XLOOKUP(A3,'2016'!A:A,'2016'!N:N,"-") -> 4 | F3: =_xlfn.XLOOKUP(A3,'2017'!A:A,'2017'!N:N,"-") -> - | G3: =_xlfn.XLOOKUP(A3,'2018'!A:A,'2018'!N:N,"-") -> - | H3: =_xlfn.XLOOKUP(A3,'2019'!A:A,'2019'!N:N,"-") -> - | I3: =_xlfn.XLOOKUP(A3,'2020'!A:A,'2020'!N:N,"-") -> - | J3: =_xlfn.XLOOKUP(A3,'2021'!A:A,'2021'!N:N,"-") -> - | K3: =_xlfn.XLOOKUP(A3,'2025'!A:A,'2025'!N:N,"-") -> - | L3: =_xlfn.XLOOKUP(A3,'2026'!A:A,'2026'!N:N,"-") -> - | M3: =SUM(B3:L3) -> 5112
A4: FZ16ST(FAZER) | B4: =_xlfn.XLOOKUP(A4,'2013'!A:A,'2013'!N:N,"-") -> 144 | C4: =_xlfn.XLOOKUP(A4,'2014'!A:A,'2014'!N:N,"-") -> 313 | D4: =_xlfn.XLOOKUP(A4,'2015'!A:A,'2015'!N:N,"-") -> 195 | E4: =_xlfn.XLOOKUP(A4,'2016'!A:A,'2016'!N:N,"-") -> 3 | F4: =_xlfn.XLOOKUP(A4,'2017'!A:A,'2017'!N:N,"-") -> - | G4: =_xlfn.XLOOKUP(A4,'2018'!A:A,'2018'!N:N,"-") -> - | H4: =_xlfn.XLOOKUP(A4,'2019'!A:A,'2019'!N:N,"-") -> - | I4: =_xlfn.XLOOKUP(A4,'2020'!A:A,'2020'!N:N,"-") -> - | J4: =_xlfn.XLOOKUP(A4,'2021'!A:A,'2021'!N:N,"-") -> - | K4: =_xlfn.XLOOKUP(A4,'2025'!A:A,'2025'!N:N,"-") -> - | L4: =_xlfn.XLOOKUP(A4,'2026'!A:A,'2026'!N:N,"-") -> - | M4: =SUM(B4:L4) -> 655
A5: FZ合計 | B5: =_xlfn.XLOOKUP(A5,'2013'!A:A,'2013'!N:N,"-") -> 2061 | C5: =_xlfn.XLOOKUP(A5,'2014'!A:A,'2014'!N:N,"-") -> 5195 | D5: =_xlfn.XLOOKUP(A5,'2015'!A:A,'2015'!N:N,"-") -> 3257 | E5: =_xlfn.XLOOKUP(A5,'2016'!A:A,'2016'!N:N,"-") -> 11 | F5: =_xlfn.XLOOKUP(A5,'2017'!A:A,'2017'!N:N,"-") -> - | G5: =_xlfn.XLOOKUP(A5,'2018'!A:A,'2018'!N:N,"-") -> - | H5: =_xlfn.XLOOKUP(A5,'2019'!A:A,'2019'!N:N,"-") -> - | I5: =_xlfn.XLOOKUP(A5,'2020'!A:A,'2020'!N:N,"-") -> - | J5: =_xlfn.XLOOKUP(A5,'2021'!A:A,'2021'!N:N,"-") -> - | K5: =_xlfn.XLOOKUP(A5,'2025'!A:A,'2025'!N:N,"-") -> - | L5: =_xlfn.XLOOKUP(A5,'2026'!A:A,'2026'!N:N,"-") -> - | M5: =SUM(B5:L5) -> 10524
A6: SZ 16 | B6: =_xlfn.XLOOKUP(A6,'2013'!A:A,'2013'!N:N,"-") -> 9 | C6: =_xlfn.XLOOKUP(A6,'2014'!A:A,'2014'!N:N,"-") -> - | D6: =_xlfn.XLOOKUP(A6,'2015'!A:A,'2015'!N:N,"-") -> - | E6: =_xlfn.XLOOKUP(A6,'2016'!A:A,'2016'!N:N,"-") -> - | F6: =_xlfn.XLOOKUP(A6,'2017'!A:A,'2017'!N:N,"-") -> - | G6: =_xlfn.XLOOKUP(A6,'2018'!A:A,'2018'!N:N,"-") -> - | H6: =_xlfn.XLOOKUP(A6,'2019'!A:A,'2019'!N:N,"-") -> - | I6: =_xlfn.XLOOKUP(A6,'2020'!A:A,'2020'!N:N,"-") -> - | J6: =_xlfn.XLOOKUP(A6,'2021'!A:A,'2021'!N:N,"-") -> - | K6: =_xlfn.XLOOKUP(A6,'2025'!A:A,'2025'!N:N,"-") -> - | L6: =_xlfn.XLOOKUP(A6,'2026'!A:A,'2026'!N:N,"-") -> - | M6: =SUM(B6:L6) -> 9
A7: SZ X | B7: =_xlfn.XLOOKUP(A7,'2013'!A:A,'2013'!N:N,"-") -> 75 | C7: =_xlfn.XLOOKUP(A7,'2014'!A:A,'2014'!N:N,"-") -> 322 | D7: =_xlfn.XLOOKUP(A7,'2015'!A:A,'2015'!N:N,"-") -> 3 | E7: =_xlfn.XLOOKUP(A7,'2016'!A:A,'2016'!N:N,"-") -> - | F7: =_xlfn.XLOOKUP(A7,'2017'!A:A,'2017'!N:N,"-") -> - | G7: =_xlfn.XLOOKUP(A7,'2018'!A:A,'2018'!N:N,"-") -> - | H7: =_xlfn.XLOOKUP(A7,'2019'!A:A,'2019'!N:N,"-") -> - | I7: =_xlfn.XLOOKUP(A7,'2020'!A:A,'2020'!N:N,"-") -> - | J7: =_xlfn.XLOOKUP(A7,'2021'!A:A,'2021'!N:N,"-") -> - | K7: =_xlfn.XLOOKUP(A7,'2025'!A:A,'2025'!N:N,"-") -> - | L7: =_xlfn.XLOOKUP(A7,'2026'!A:A,'2026'!N:N,"-") -> - | M7: =SUM(B7:L7) -> 400
A8: SZ R | B8: =_xlfn.XLOOKUP(A8,'2013'!A:A,'2013'!N:N,"-") -> 168 | C8: =_xlfn.XLOOKUP(A8,'2014'!A:A,'2014'!N:N,"-") -> 105 | D8: =_xlfn.XLOOKUP(A8,'2015'!A:A,'2015'!N:N,"-") -> 1 | E8: =_xlfn.XLOOKUP(A8,'2016'!A:A,'2016'!N:N,"-") -> - | F8: =_xlfn.XLOOKUP(A8,'2017'!A:A,'2017'!N:N,"-") -> - | G8: =_xlfn.XLOOKUP(A8,'2018'!A:A,'2018'!N:N,"-") -> - | H8: =_xlfn.XLOOKUP(A8,'2019'!A:A,'2019'!N:N,"-") -> - | I8: =_xlfn.XLOOKUP(A8,'2020'!A:A,'2020'!N:N,"-") -> - | J8: =_xlfn.XLOOKUP(A8,'2021'!A:A,'2021'!N:N,"-") -> - | K8: =_xlfn.XLOOKUP(A8,'2025'!A:A,'2025'!N:N,"-") -> - | L8: =_xlfn.XLOOKUP(A8,'2026'!A:A,'2026'!N:N,"-") -> - | M8: =SUM(B8:L8) -> 274
A9: XTZ 125E | B9: =_xlfn.XLOOKUP(A9,'2013'!A:A,'2013'!N:N,"-") -> 2 | C9: =_xlfn.XLOOKUP(A9,'2014'!A:A,'2014'!N:N,"-") -> 5 | D9: =_xlfn.XLOOKUP(A9,'2015'!A:A,'2015'!N:N,"-") -> 2 | E9: =_xlfn.XLOOKUP(A9,'2016'!A:A,'2016'!N:N,"-") -> - | F9: =_xlfn.XLOOKUP(A9,'2017'!A:A,'2017'!N:N,"-") -> - | G9: =_xlfn.XLOOKUP(A9,'2018'!A:A,'2018'!N:N,"-") -> - | H9: =_xlfn.XLOOKUP(A9,'2019'!A:A,'2019'!N:N,"-") -> - | I9: =_xlfn.XLOOKUP(A9,'2020'!A:A,'2020'!N:N,"-") -> - | J9: =_xlfn.XLOOKUP(A9,'2021'!A:A,'2021'!N:N,"-") -> - | K9: =_xlfn.XLOOKUP(A9,'2025'!A:A,'2025'!N:N,"-") -> - | L9: =_xlfn.XLOOKUP(A9,'2026'!A:A,'2026'!N:N,"-") -> - | M9: =SUM(B9:L9) -> 9
A10: YZ 125 | B10: =_xlfn.XLOOKUP(A10,'2013'!A:A,'2013'!N:N,"-") -> 25 | C10: =_xlfn.XLOOKUP(A10,'2014'!A:A,'2014'!N:N,"-") -> 3 | D10: =_xlfn.XLOOKUP(A10,'2015'!A:A,'2015'!N:N,"-") -> - | E10: =_xlfn.XLOOKUP(A10,'2016'!A:A,'2016'!N:N,"-") -> - | F10: =_xlfn.XLOOKUP(A10,'2017'!A:A,'2017'!N:N,"-") -> - | G10: =_xlfn.XLOOKUP(A10,'2018'!A:A,'2018'!N:N,"-") -> - | H10: =_xlfn.XLOOKUP(A10,'2019'!A:A,'2019'!N:N,"-") -> - | I10: =_xlfn.XLOOKUP(A10,'2020'!A:A,'2020'!N:N,"-") -> - | J10: =_xlfn.XLOOKUP(A10,'2021'!A:A,'2021'!N:N,"-") -> - | K10: =_xlfn.XLOOKUP(A10,'2025'!A:A,'2025'!N:N,"-") -> - | L10: =_xlfn.XLOOKUP(A10,'2026'!A:A,'2026'!N:N,"-") -> - | M10: =SUM(B10:L10) -> 28
A11: YBR110 | B11: =_xlfn.XLOOKUP(A11,'2013'!A:A,'2013'!N:N,"-") -> - | C11: =_xlfn.XLOOKUP(A11,'2014'!A:A,'2014'!N:N,"-") -> 3 | D11: =_xlfn.XLOOKUP(A11,'2015'!A:A,'2015'!N:N,"-") -> 51 | E11: =_xlfn.XLOOKUP(A11,'2016'!A:A,'2016'!N:N,"-") -> - | F11: =_xlfn.XLOOKUP(A11,'2017'!A:A,'2017'!N:N,"-") -> 2 | G11: =_xlfn.XLOOKUP(A11,'2018'!A:A,'2018'!N:N,"-") -> 4 | H11: =_xlfn.XLOOKUP(A11,'2019'!A:A,'2019'!N:N,"-") -> 2 | I11: =_xlfn.XLOOKUP(A11,'2020'!A:A,'2020'!N:N,"-") -> 1 | J11: =_xlfn.XLOOKUP(A11,'2021'!A:A,'2021'!N:N,"-") -> - | K11: =_xlfn.XLOOKUP(A11,'2025'!A:A,'2025'!N:N,"-") -> - | L11: =_xlfn.XLOOKUP(A11,'2026'!A:A,'2026'!N:N,"-") -> - | M11: =SUM(B11:L11) -> 63
A12: YBR125 | B12: =_xlfn.XLOOKUP(A12,'2013'!A:A,'2013'!N:N,"-") -> 2 | C12: =_xlfn.XLOOKUP(A12,'2014'!A:A,'2014'!N:N,"-") -> - | D12: =_xlfn.XLOOKUP(A12,'2015'!A:A,'2015'!N:N,"-") -> - | E12: =_xlfn.XLOOKUP(A12,'2016'!A:A,'2016'!N:N,"-") -> - | F12: =_xlfn.XLOOKUP(A12,'2017'!A:A,'2017'!N:N,"-") -> - | G12: =_xlfn.XLOOKUP(A12,'2018'!A:A,'2018'!N:N,"-") -> - | H12: =_xlfn.XLOOKUP(A12,'2019'!A:A,'2019'!N:N,"-") -> - | I12: =_xlfn.XLOOKUP(A12,'2020'!A:A,'2020'!N:N,"-") -> - | J12: =_xlfn.XLOOKUP(A12,'2021'!A:A,'2021'!N:N,"-") -> - | K12: =_xlfn.XLOOKUP(A12,'2025'!A:A,'2025'!N:N,"-") -> - | L12: =_xlfn.XLOOKUP(A12,'2026'!A:A,'2026'!N:N,"-") -> - | M12: =SUM(B12:L12) -> 2
A13: RAY Original | B13: =_xlfn.XLOOKUP(A13,'2013'!A:A,'2013'!N:N,"-") -> 1741 | C13: =_xlfn.XLOOKUP(A13,'2014'!A:A,'2014'!N:N,"-") -> 3291 | D13: =_xlfn.XLOOKUP(A13,'2015'!A:A,'2015'!N:N,"-") -> 1515 | E13: =_xlfn.XLOOKUP(A13,'2016'!A:A,'2016'!N:N,"-") -> 21 | F13: =_xlfn.XLOOKUP(A13,'2017'!A:A,'2017'!N:N,"-") -> - | G13: =_xlfn.XLOOKUP(A13,'2018'!A:A,'2018'!N:N,"-") -> - | H13: =_xlfn.XLOOKUP(A13,'2019'!A:A,'2019'!N:N,"-") -> - | I13: =_xlfn.XLOOKUP(A13,'2020'!A:A,'2020'!N:N,"-") -> - | J13: =_xlfn.XLOOKUP(A13,'2021'!A:A,'2021'!N:N,"-") -> - | K13: =_xlfn.XLOOKUP(A13,'2025'!A:A,'2025'!N:N,"-") -> - | L13: =_xlfn.XLOOKUP(A13,'2026'!A:A,'2026'!N:N,"-") -> - | M13: =SUM(B13:L13) -> 6568
... A57: Ray ZR -Street Rally | B57: =_xlfn.XLOOKUP(A57,'2013'!A:A,'2013'!N:N,"-") -> - | C57: =_xlfn.XLOOKUP(A57,'2014'!A:A,'2014'!N:N,"-") -> - | D57: =_xlfn.XLOOKUP(A57,'2015'!A:A,'2015'!N:N,"-") -> - | E57: =_xlfn.XLOOKUP(A57,'2016'!A:A,'2016'!N:N,"-") -> - | F57: =_xlfn.XLOOKUP(A57,'2017'!A:A,'2017'!N:N,"-") -> - | G57: =_xlfn.XLOOKUP(A57,'2018'!A:A,'2018'!N:N,"-") -> - | H57: =_xlfn.XLOOKUP(A57,'2019'!A:A,'2019'!N:N,"-") -> - | I57: =_xlfn.XLOOKUP(A57,'2020'!A:A,'2020'!N:N,"-") -> - | J57: =_xlfn.XLOOKUP(A57,'2021'!A:A,'2021'!N:N,"-") -> - | K57: =_xlfn.XLOOKUP(A57,'2025'!A:A,'2025'!N:N,"-") -> 1305 | L57: =_xlfn.XLOOKUP(A57,'2026'!A:A,'2026'!N:N,"-") -> 217 | M57: =SUM(B57:L57) -> 1522

Sheet 2026
B1: JAN | C1: FEB | D1: MAR | E1: APR | F1: MAY | G1: JUN | H1: JUL | I1: AUG | J1: SEP | K1: OCT | L1: NOV | M1: DEC | N1: Total
A2: FZ - V2 | B2: 615 | N2: =M2+L2+K2+J2+I2+H2+G2+F2+E2+D2+C2+B2 -> 615
A3: FZ - V4 | B3: 225 | N3: =M3+L3+K3+J3+I3+H3+G3+F3+E3+D3+C3+B3 -> 225
A4: FZ -S- FI | B4: 263 | N4: =M4+L4+K4+J4+I4+H4+G4+F4+E4+D4+C4+B4 -> 263
A5: MT-15 | B5: 243 | N5: =M5+L5+K5+J5+I5+H5+G5+F5+E5+D5+C5+B5 -> 243
A6: YZF-R15 | B6: 81 | N6: =M6+L6+K6+J6+I6+H6+G6+F6+E6+D6+C6+B6 -> 81
A7: Ray ZR - 125 Disc | B7: 853 | N7: =M7+L7+K7+J7+I7+H7+G7+F7+E7+D7+C7+B7 -> 853
A8: Ray ZR - 125 Street Rally | B8: 444 | N8: =M8+L8+K8+J8+I8+H8+G8+F8+E8+D8+C8+B8 -> 444
A9: Ray ZR -Disc | B9: 314 | N9: =M9+L9+K9+J9+I9+H9+G9+F9+E9+D9+C9+B9 -> 314
A10: Ray ZR -Street Rally | B10: 217 | N10: =M10+L10+K10+J10+I10+H10+G10+F10+E10+D10+C10+B10 -> 217

Sheet 2025
B1: JAN | C1: FEB | D1: MAR | E1: APR | F1: MAY | G1: JUN | H1: JUL | I1: AUG | J1: SEP | K1: OCT | L1: NOV | M1: DEC | N1: Total
A2: FZ - V2 | F2: 109 | G2: 468 | H2: 499 | I2: 1210 | J2: 447 | K2: 64 | L2: 870 | M2: 1255 | N2: =M2+L2+K2+J2+I2+H2+G2+F2+E2+D2+C2+B2 -> 4922
A3: FZ - V4 | E3: 1 | F3: 56 | G3: 314 | H3: 561 | I3: 713 | J3: 927 | K3: 346 | L3: 769 | M3: 386 | N3: =M3+L3+K3+J3+I3+H3+G3+F3+E3+D3+C3+B3 -> 4073
A4: FZ -S- FI | M4: 745 | N4: =M4+L4+K4+J4+I4+H4+G4+F4+E4+D4+C4+B4 -> 745
A5: MT-15 | F5: 71 | G5: 131 | H5: 127 | I5: 150 | J5: 436 | K5: 321 | L5: 65 | M5: 350 | N5: =M5+L5+K5+J5+I5+H5+G5+F5+E5+D5+C5+B5 -> 1651
A6: YZF-R15 | F6: 60 | G6: 45 | H6: 72 | I6: 80 | J6: 148 | K6: 270 | L6: 85 | M6: 89 | N6: =M6+L6+K6+J6+I6+H6+G6+F6+E6+D6+C6+B6 -> 849
A7: Ray ZR - 125 Disc | F7: 228 | G7: 174 | H7: 337 | I7: 406 | J7: 621 | K7: 378 | L7: 489 | M7: 801 | N7: =M7+L7+K7+J7+I7+H7+G7+F7+E7+D7+C7+B7 -> 3434
A8: Ray ZR - 125 Street Rally | F8: 122 | G8: 93 | H8: 184 | I8: 185 | J8: 423 | K8: 428 | L8: 327 | M8: 563 | N8: =M8+L8+K8+J8+I8+H8+G8+F8+E8+D8+C8+B8 -> 2325
A9: Ray ZR -Disc | F9: 88 | G9: 356 | H9: 336 | I9: 476 | J9: 407 | K9: 286 | L9: 498 | M9: 333 | N9: =M9+L9+K9+J9+I9+H9+G9+F9+E9+D9+C9+B9 -> 2780
A10: Ray ZR -Street Rally | G10: 159 | H10: 227 | I10: 336 | J10: 116 | K10: 30 | L10: 161 | M10: 276 | N10: =M10+L10+K10+J10+I10+H10+G10+F10+E10+D10+C10+B10 -> 1305

Sheet 2021
B1: JAN | C1: FEB | D1: MAR | E1: APR | F1: MAY | G1: JUN | H1: JUL | I1: AUG | J1: SEP | K1: OCT | L1: NOV | M1: DEC | N1: Total
A2: YZF-R15 | B2: 1 | C2: 1 | E2: 1 | N2: =M2+L2+K2+J2+I2+H2+G2+F2+E2+D2+C2+B2 -> 3
A3: FZN150 FZ ver.2 | D3: 2 | N3: =M3+L3+K3+J3+I3+H3+G3+F3+E3+D3+C3+B3 -> 2
A4: FZN150D(Rear Disc.) | D4: 1 | N4: =M4+L4+K4+J4+I4+H4+G4+F4+E4+D4+C4+B4 -> 1
A5: FZN250 | B5: 1 | N5: =M5+L5+K5+J5+I5+H5+G5+F5+E5+D5+C5+B5 -> 1
A6: FZH150 FAZER ver.2 | B6: 7 | N6: =M6+L6+K6+J6+I6+H6+G6+F6+E6+D6+C6+B6 -> 7
A7: MT-15 | B7: 4 | N7: =M7+L7+K7+J7+I7+H7+G7+F7+E7+D7+C7+B7 -> 4
A8: YC125-5 SALUTO DISK | B8: 8 | D8: 10 | N8: =M8+L8+K8+J8+I8+H8+G8+F8+E8+D8+C8+B8 -> 18
A9: Saluto Rx | C9: 6 | D9: 1 | N9: =M9+L9+K9+J9+I9+H9+G9+F9+E9+D9+C9+B9 -> 7
A10: Arroex | B10: 1 | N10: =M10+L10+K10+J10+I10+H10+G10+F10+E10+D10+C10+B10 -> 1
A11: Fascino 125cc | C11: 1 | N11: =M11+L11+K11+J11+I11+H11+G11+F11+E11+D11+C11+B11 -> 1
A12: Ray ZR-DK-125cc | B12: 1 | C12: 1 | N12: =M12+L12+K12+J12+I12+H12+G12+F12+E12+D12+C12+B12 -> 2
A13: XC115C FASCINO | F13: 1 | N13: =M13+L13+K13+J13+I13+H13+G13+F13+E13+D13+C13+B13 -> 1
A14: XC115F ALPHA | D14: 1 | N14: =M14+L14+K14+J14+I14+H14+G14+F14+E14+D14+C14+B14 -> 1
A15: XC115F ALPHA DISC | B15: 1 | N15: =M15+L15+K15+J15+I15+H15+G15+F15+E15+D15+C15+B15 -> 1
A16: XC115B RAY ZR(Drum) | B16: 1 | D16: 2 | E16: 3 | N16: =M16+L16+K16+J16+I16+H16+G16+F16+E16+D16+C16+B16 -> 6
A17: XC115BD RAY ZR(Disk) | B17: 1 | D17: 3 | E17: 1 | N17: =M17+L17+K17+J17+I17+H17+G17+F17+E17+D17+C17+B17 -> 5
A18: XC115BD RAY SR(Disk) | D18: 1 | N18: =M18+L18+K18+J18+I18+H18+G18+F18+E18+D18+C18+B18 -> 1

Sheet 2020
B1: JAN | C1: FEB | D1: MAR | E1: APR | F1: MAY | G1: JUN | H1: JUL | I1: AUG | J1: SEP | K1: OCT | L1: NOV | M1: DEC | N1: Total
A2: YZF-R15 | B2: 154 | C2: 153 | D2: 96 | E2: 7 | F2: 40 | G2: 101 | H2: 139 | I2: 96 | J2: 79 | K2: 37 | L2: 26 | M2: 15 | N2: =M2+L2+K2+J2+I2+H2+G2+F2+E2+D2+C2+B2 -> 943
A3: FZN150 FZ ver.2 | B3: 784 | C3: 738 | D3: 445 | E3: 17 | F3: 337 | G3: 460 | H3: 119 | I3: 409 | J3: 96 | K3: 8 | L3: 1 | M3: 7 | N3: =M3+L3+K3+J3+I3+H3+G3+F3+E3+D3+C3+B3 -> 3421
A4: FZN150D FZS ver.2 | B4: 1 | C4: 1 | D4: 1 | H4: 2 | I4: 0 | N4: =M4+L4+K4+J4+I4+H4+G4+F4+E4+D4+C4+B4 -> 5
A5: FZN150 FZ ver.3 | B5: 379 | C5: 381 | D5: 308 | E5: 32 | F5: 155 | G5: 342 | H5: 347 | I5: 126 | J5: 34 | K5: 4 | L5: 5 | M5: 2 | N5: =M5+L5+K5+J5+I5+H5+G5+F5+E5+D5+C5+B5 -> 2115
A6: FZN150D FZS ver.3 | B6: 541 | C6: 518 | D6: 318 | E6: 24 | F6: 196 | G6: 527 | H6: 643 | I6: 219 | J6: 43 | K6: 8 | L6: 7 | M6: 5 | N6: =M6+L6+K6+J6+I6+H6+G6+F6+E6+D6+C6+B6 -> 3049
A7: FZN250 | B7: 1 | C7: 2 | D7: 1 | F7: 10 | G7: 23 | H7: 10 | I7: 1 | M7: 2 | N7: =M7+L7+K7+J7+I7+H7+G7+F7+E7+D7+C7+B7 -> 50
A8: FZH150 FAZER ver.2 | B8: 48 | C8: 37 | D8: 44 | E8: 2 | F8: 21 | G8: 36 | H8: 58 | I8: 64 | J8: 77 | K8: 31 | L8: 14 | M8: 10 | N8: =M8+L8+K8+J8+I8+H8+G8+F8+E8+D8+C8+B8 -> 442
A9: MT-15 | B9: 166 | C9: 169 | D9: 120 | E9: 12 | F9: 69 | G9: 136 | H9: 236 | I9: 171 | J9: 151 | K9: 67 | L9: 24 | M9: 22 | N9: =M9+L9+K9+J9+I9+H9+G9+F9+E9+D9+C9+B9 -> 1343
A10: YC125-5 SALUTO DISK | B10: 31 | C10: 32 | D10: 10 | E10: 2 | F10: 5 | G10: 16 | H10: 17 | I10: 25 | J10: 40 | K10: 23 | L10: 25 | M10: 11 | N10: =M10+L10+K10+J10+I10+H10+G10+F10+E10+D10+C10+B10 -> 237
A11: Saluto Rx | B11: 1 | I11: 0 | N11: =M11+L11+K11+J11+I11+H11+G11+F11+E11+D11+C11+B11 -> 1
A12: YBR110 | I12: 0 | L12: 1 | N12: =M12+L12+K12+J12+I12+H12+G12+F12+E12+D12+C12+B12 -> 1
A13: N Max | B13: 65 | C13: 35 | D13: 38 | E13: 1 | F13: 23 | G13: 125 | H13: 212 | I13: 73 | J13: 35 | K13: 2 | L13: 2 | M13: 1 | N13: =M13+L13+K13+J13+I13+H13+G13+F13+E13+D13+C13+B13 -> 612
A14: Arroex | G14: 11 | H14: 23 | I14: 16 | J14: 12 | K14: 8 | L14: 1 | N14: =M14+L14+K14+J14+I14+H14+G14+F14+E14+D14+C14+B14 -> 71
A15: Ray ZR-DK-125cc | I15: 0 | L15: 17 | M15: 37 | N15: =M15+L15+K15+J15+I15+H15+G15+F15+E15+D15+C15+B15 -> 54
A16: Ray ZR-SR-125cc | I16: 0 | K16: 17 | N16: =M16+L16+K16+J16+I16+H16+G16+F16+E16+D16+C16+B16 -> 17
A17: XC115B RAY Z | I17: 0 | J17: 1 | N17: =M17+L17+K17+J17+I17+H17+G17+F17+E17+D17+C17+B17 -> 1
A18: RAY Z (NEW) | B18: 81 | C18: 78 | D18: 33 | E18: 7 | F18: 25 | G18: 78 | H18: 90 | I18: 35 | J18: 7 | L18: 1 | N18: =M18+L18+K18+J18+I18+H18+G18+F18+E18+D18+C18+B18 -> 435
A19: XC115C FASCINO | B19: 74 | C19: 94 | D19: 58 | E19: 6 | F19: 34 | G19: 80 | H19: 86 | I19: 83 | J19: 58 | K19: 23 | L19: 5 | M19: 4 | N19: =M19+L19+K19+J19+I19+H19+G19+F19+E19+D19+C19+B19 -> 605
A20: XC115F ALPHA | C20: 1 | I20: 0 | M20: 5 | N20: =M20+L20+K20+J20+I20+H20+G20+F20+E20+D20+C20+B20 -> 6
A21: XC115F ALPHA DISC | B21: 13 | C21: 30 | D21: 20 | E21: 5 | F21: 14 | G21: 26 | H21: 55 | I21: 37 | J21: 22 | K21: 1 | L21: 2 | M21: 3 | N21: =M21+L21+K21+J21+I21+H21+G21+F21+E21+D21+C21+B21 -> 228
A22: XC115B RAY ZR(Drum) | B22: 741 | C22: 744 | D22: 474 | E22: 57 | F22: 343 | G22: 470 | H22: 433 | I22: 329 | J22: 111 | K22: 12 | L22: 5 | M22: 10 | N22: =M22+L22+K22+J22+I22+H22+G22+F22+E22+D22+C22+B22 -> 3729
A23: XC115BD RAY ZR(Disk) | B23: 1099 | C23: 1167 | D23: 754 | E23: 93 | F23: 624 | G23: 1155 | H23: 784 | I23: 162 | J23: 47 | K23: 6 | L23: 7 | M23: 9 | N23: =M23+L23+K23+J23+I23+H23+G23+F23+E23+D23+C23+B23 -> 5907
A24: XC115BD RAY SR(Disk) | B24: 737 | C24: 663 | D24: 513 | E24: 62 | F24: 338 | G24: 415 | H24: 310 | I24: 459 | J24: 164 | L24: 4 | M24: 5 | N24: =M24+L24+K24+J24+I24+H24+G24+F24+E24+D24+C24+B24 -> 3670

Sheet 2019
B1: JAN | C1: FEB | D1: MAR | E1: APR | F1: MAY | G1: JUN | H1: JUL | I1: AUG | J1: SEP | K1: OCT | L1: NOV | M1: DEC | N1: Total
A2: YZF-R15 | B2: 45 | C2: 93 | D2: 74 | E2: 116 | F2: 87 | G2: 99 | H2: 154 | I2: 130 | J2: 139 | K2: 129 | L2: 100 | M2: 140 | N2: =M2+L2+K2+J2+I2+H2+G2+F2+E2+D2+C2+B2 -> 1306
A3: FZN150 FZ ver.2 | B3: 445 | C3: 451 | D3: 740 | E3: 625 | F3: 332 | G3: 324 | H3: 457 | I3: 621 | J3: 513 | K3: 484 | L3: 461 | M3: 698 | N3: =M3+L3+K3+J3+I3+H3+G3+F3+E3+D3+C3+B3 -> 6151
A4: FZN150D FZS ver.2 | B4: 572 | C4: 519 | D4: 665 | E4: 609 | F4: 481 | G4: 299 | H4: 215 | I4: 145 | J4: 61 | K4: 23 | L4: 6 | M4: 10 | N4: =M4+L4+K4+J4+I4+H4+G4+F4+E4+D4+C4+B4 -> 3605
A5: FZN150 FZ ver.3 | F5: 228 | G5: 478 | H5: 451 | I5: 395 | J5: 377 | K5: 393 | L5: 330 | M5: 434 | N5: =M5+L5+K5+J5+I5+H5+G5+F5+E5+D5+C5+B5 -> 3086
A6: FZN150D FZS ver.3 | F6: 325 | G6: 566 | H6: 625 | I6: 510 | J6: 475 | K6: 385 | L6: 397 | M6: 627 | N6: =M6+L6+K6+J6+I6+H6+G6+F6+E6+D6+C6+B6 -> 3910
A7: FZN150D(Rear Disc.) | B7: 463 | C7: 429 | D7: 682 | E7: 653 | F7: 314 | G7: 112 | H7: 52 | I7: 29 | J7: 2 | K7: 5 | L7: 0 | N7: =M7+L7+K7+J7+I7+H7+G7+F7+E7+D7+C7+B7 -> 2741
A8: FZN250 | B8: 9 | C8: 3 | D8: 8 | E8: 1 | F8: 3 | G8: 1 | H8: 1 | I8: 3 | J8: 3 | K8: 1 | L8: 3 | M8: 3 | N8: =M8+L8+K8+J8+I8+H8+G8+F8+E8+D8+C8+B8 -> 39
A9: FZH150 FAZER ver.2 | B9: 71 | C9: 68 | D9: 91 | E9: 79 | F9: 67 | G9: 73 | H9: 70 | I9: 47 | J9: 53 | K9: 61 | L9: 50 | M9: 56 | N9: =M9+L9+K9+J9+I9+H9+G9+F9+E9+D9+C9+B9 -> 786
A10: MT-15 | I10: 137 | J10: 220 | K10: 181 | L10: 165 | M10: 158 | N10: =M10+L10+K10+J10+I10+H10+G10+F10+E10+D10+C10+B10 -> 861
A11: YC125-5 SALUTO DISK | B11: 28 | C11: 14 | D11: 30 | E11: 19 | F11: 22 | G11: 28 | H11: 37 | I11: 60 | J11: 40 | K11: 28 | L11: 28 | M11: 33 | N11: =M11+L11+K11+J11+I11+H11+G11+F11+E11+D11+C11+B11 -> 367
A12: Saluto Rx | I12: 1 | J12: 1 | K12: 1 | N12: =M12+L12+K12+J12+I12+H12+G12+F12+E12+D12+C12+B12 -> 3
A13: YBR110 | I13: 2 | N13: =M13+L13+K13+J13+I13+H13+G13+F13+E13+D13+C13+B13 -> 2
A14: N Max | L14: 105 | M14: 115 | N14: =M14+L14+K14+J14+I14+H14+G14+F14+E14+D14+C14+B14 -> 220
A15: XC115B RAY Z | F15: 67 | I15: 1 | J15: 2 | N15: =M15+L15+K15+J15+I15+H15+G15+F15+E15+D15+C15+B15 -> 70
A16: RAY Z (NEW) | B16: 99 | C16: 65 | D16: 101 | E16: 102 | G16: 62 | H16: 51 | I16: 97 | J16: 107 | K16: 74 | L16: 42 | M16: 79 | N16: =M16+L16+K16+J16+I16+H16+G16+F16+E16+D16+C16+B16 -> 879
A17: XC115C FASCINO | B17: 43 | C17: 41 | D17: 40 | E17: 58 | F17: 61 | G17: 76 | H17: 109 | I17: 126 | J17: 80 | K17: 44 | L17: 40 | M17: 56 | N17: =M17+L17+K17+J17+I17+H17+G17+F17+E17+D17+C17+B17 -> 774
A18: XC115F ALPHA | C18: 1 | D18: 4 | E18: 2 | H18: 3 | I18: 8 | J18: 13 | K18: 3 | L18: 0 | M18: 1 | N18: =M18+L18+K18+J18+I18+H18+G18+F18+E18+D18+C18+B18 -> 35
A19: XC115F ALPHA DISC | B19: 49 | C19: 33 | D19: 41 | E19: 31 | F19: 24 | G19: 28 | H19: 24 | I19: 50 | J19: 32 | K19: 22 | L19: 19 | M19: 21 | N19: =M19+L19+K19+J19+I19+H19+G19+F19+E19+D19+C19+B19 -> 374
A20: XC115B RAY ZR(Drum) | B20: 687 | C20: 669 | D20: 831 | E20: 745 | F20: 444 | G20: 487 | H20: 757 | I20: 870 | J20: 617 | K20: 379 | L20: 457 | M20: 685 | N20: =M20+L20+K20+J20+I20+H20+G20+F20+E20+D20+C20+B20 -> 7628
A21: XC115BD RAY ZR(Disk) | B21: 971 | C21: 834 | D21: 1056 | E21: 1010 | F21: 867 | G21: 1154 | H21: 1214 | I21: 1043 | J21: 900 | K21: 961 | L21: 913 | M21: 1247 | N21: =M21+L21+K21+J21+I21+H21+G21+F21+E21+D21+C21+B21 -> 12170
A22: XC115BD RAY SR(Disk) | B22: 870 | C22: 724 | D22: 954 | E22: 848 | F22: 764 | G22: 791 | H22: 740 | I22: 842 | J22: 725 | K22: 678 | L22: 536 | M22: 609 | N22: =M22+L22+K22+J22+I22+H22+G22+F22+E22+D22+C22+B22 -> 9081

Sheet 2018
B1: JAN | C1: FEB | D1: MAR | E1: APR | F1: MAY | G1: JUN | H1: JUL | I1: AUG | J1: SEP | K1: OCT | L1: NOV | M1: DEC | N1: Total
A2: YZF-R15 | B2: 15 | C2: 5 | D2: 2 | E2: 2 | K2: 94 | L2: 15 | M2: 36 | N2: =M2+L2+K2+J2+I2+H2+G2+F2+E2+D2+C2+B2 -> 169
A3: R3 | B3: 6 | C3: 2 | D3: 1 | E3: 5 | F3: 1 | N3: =M3+L3+K3+J3+I3+H3+G3+F3+E3+D3+C3+B3 -> 15
A4: FZN150 FZ ver.2 | B4: 463 | C4: 394 | D4: 402 | E4: 436 | F4: 593 | G4: 670 | H4: 669 | I4: 658 | J4: 603 | K4: 564 | L4: 463 | M4: 589 | N4: =M4+L4+K4+J4+I4+H4+G4+F4+E4+D4+C4+B4 -> 6504
A5: FZN150D FZS ver.2 | B5: 781 | C5: 821 | D5: 1075 | E5: 1169 | F5: 921 | G5: 916 | H5: 923 | I5: 936 | J5: 798 | K5: 739 | L5: 564 | M5: 772 | N5: =M5+L5+K5+J5+I5+H5+G5+F5+E5+D5+C5+B5 -> 10415
A6: FZN150D(Rear Disc.) | J6: 169 | K6: 475 | L6: 182 | M6: 429 | N6: =M6+L6+K6+J6+I6+H6+G6+F6+E6+D6+C6+B6 -> 1255
A7: FZN250 | B7: 19 | C7: 11 | D7: 16 | E7: 17 | F7: 12 | G7: 16 | H7: 14 | I7: 16 | J7: 7 | K7: 11 | L7: 5 | M7: 7 | N7: =M7+L7+K7+J7+I7+H7+G7+F7+E7+D7+C7+B7 -> 151
A8: FZH150 FAZER ver.2 | B8: 112 | C8: 83 | D8: 97 | E8: 141 | F8: 106 | G8: 95 | H8: 94 | I8: 91 | J8: 109 | K8: 99 | L8: 49 | M8: 105 | N8: =M8+L8+K8+J8+I8+H8+G8+F8+E8+D8+C8+B8 -> 1181
A9: YC125-5 SALUTO DISK | B9: 46 | C9: 38 | D9: 44 | E9: 37 | F9: 28 | G9: 35 | H9: 47 | I9: 68 | J9: 47 | K9: 47 | L9: 46 | M9: 21 | N9: =M9+L9+K9+J9+I9+H9+G9+F9+E9+D9+C9+B9 -> 504
A10: YBR110 | C10: 1 | H10: 2 | J10: 1 | N10: =M10+L10+K10+J10+I10+H10+G10+F10+E10+D10+C10+B10 -> 4
A11: RAY Z (NEW) | B11: 72 | C11: 90 | D11: 125 | E11: 179 | F11: 171 | G11: 133 | H11: 127 | I11: 143 | J11: 144 | K11: 130 | L11: 85 | M11: 98 | N11: =M11+L11+K11+J11+I11+H11+G11+F11+E11+D11+C11+B11 -> 1497
A12: XC115C FASCINO | B12: 60 | C12: 69 | D12: 83 | E12: 70 | F12: 64 | G12: 80 | H12: 51 | I12: 67 | J12: 54 | K12: 43 | L12: 39 | M12: 46 | N12: =M12+L12+K12+J12+I12+H12+G12+F12+E12+D12+C12+B12 -> 726
A13: XC115F ALPHA | B13: 13 | C13: 11 | D13: 8 | E13: 7 | F13: 4 | G13: 8 | H13: 13 | I13: 19 | J13: 10 | K13: 5 | L13: 0 | M13: 1 | N13: =M13+L13+K13+J13+I13+H13+G13+F13+E13+D13+C13+B13 -> 99
A14: XC115F ALPHA DISC | E14: 32 | F14: 129 | G14: 40 | H14: 66 | I14: 89 | J14: 69 | K14: 46 | L14: 20 | M14: 46 | N14: =M14+L14+K14+J14+I14+H14+G14+F14+E14+D14+C14+B14 -> 537
A15: XC115B RAY ZR(Drum) | B15: 1581 | C15: 1644 | D15: 1503 | E15: 1444 | F15: 1184 | G15: 1035 | H15: 1028 | I15: 1182 | J15: 1008 | K15: 821 | L15: 483 | M15: 734 | N15: =M15+L15+K15+J15+I15+H15+G15+F15+E15+D15+C15+B15 -> 13647
A16: XC115BD RAY ZR(Disk) | B16: 914 | C16: 1050 | D16: 1261 | E16: 1717 | F16: 1915 | G16: 2020 | H16: 1850 | I16: 1636 | J16: 1347 | K16: 1173 | L16: 812 | M16: 1109 | N16: =M16+L16+K16+J16+I16+H16+G16+F16+E16+D16+C16+B16 -> 16804
A17: XC115BD RAY SR(Disk) | J17: 304 | K17: 815 | L17: 468 | M17: 743 | N17: =M17+L17+K17+J17+I17+H17+G17+F17+E17+D17+C17+B17 -> 2330

Sheet 2017
B1: JAN | C1: FEB | D1: MAR | E1: APR | F1: MAY | G1: JUN | H1: JUL | I1: AUG | J1: SEP | K1: OCT | L1: NOV | M1: DEC | N1: Total
A2: YZF-R15 | B2: 10 | C2: 10 | D2: 4 | E2: 7 | F2: 3 | G2: 11 | H2: 3 | I2: 8 | J2: 6 | K2: 5 | L2: 9 | M2: 15 | N2: =B2+C2+D2+E2+F2+G2+H2+I2+J2+K2+L2+M2 -> 91
A3: XJ900PCZ6 | L3: 8 | N3: =B3+C3+D3+E3+F3+G3+H3+I3+J3+K3+L3+M3 -> 8
A4: FZ16 | K4: 1 | M4: 0 | N4: =B4+C4+D4+E4+F4+G4+H4+I4+J4+K4+L4+M4 -> 1
A5: FZN150 FZ ver.2 | B5: 188 | C5: 196 | D5: 164 | E5: 189 | F5: 269 | G5: 333 | H5: 358 | I5: 273 | J5: 135 | K5: 351 | L5: 433 | M5: 717 | N5: =B5+C5+D5+E5+F5+G5+H5+I5+J5+K5+L5+M5 -> 3606
A6: FZN150D FZS ver.2 | B6: 637 | C6: 832 | D6: 716 | E6: 902 | F6: 773 | G6: 706 | H6: 704 | I6: 821 | J6: 927 | K6: 696 | L6: 671 | M6: 863 | N6: =B6+C6+D6+E6+F6+G6+H6+I6+J6+K6+L6+M6 -> 9248
A7: FZN250 | I7: 1 | K7: 17 | L7: 8 | M7: 11 | N7: =B7+C7+D7+E7+F7+G7+H7+I7+J7+K7+L7+M7 -> 37
A8: FZH150 FAZER ver.2 | B8: 93 | C8: 86 | D8: 72 | E8: 56 | F8: 95 | G8: 110 | H8: 94 | I8: 95 | J8: 91 | K8: 73 | L8: 72 | M8: 122 | N8: =B8+C8+D8+E8+F8+G8+H8+I8+J8+K8+L8+M8 -> 1059
A9: YC125-5 SALUTO DISK | B9: 58 | C9: 59 | D9: 84 | E9: 71 | F9: 62 | G9: 46 | H9: 34 | I9: 97 | J9: 36 | K9: 27 | L9: 35 | M9: 59 | N9: =B9+C9+D9+E9+F9+G9+H9+I9+J9+K9+L9+M9 -> 668
A10: YBR110 | F10: 1 | I10: 1 | M10: 0 | N10: =B10+C10+D10+E10+F10+G10+H10+I10+J10+K10+L10+M10 -> 2
A11: XC115B RAY Z | B11: 6 | C11: 2 | D11: 3 | E11: 2 | F11: 2 | H11: 1 | I11: 3 | K11: 7 | M11: 3 | N11: =B11+C11+D11+E11+F11+G11+H11+I11+J11+K11+L11+M11 -> 29
A12: RAY Z (NEW) | L12: 35 | M12: 84 | N12: =B12+C12+D12+E12+F12+G12+H12+I12+J12+K12+L12+M12 -> 119
A13: XC115C FASCINO | B13: 32 | C13: 35 | D13: 38 | E13: 28 | F13: 31 | G13: 27 | H13: 25 | I13: 26 | J13: 44 | K13: 26 | L13: 51 | M13: 48 | N13: =B13+C13+D13+E13+F13+G13+H13+I13+J13+K13+L13+M13 -> 411
A14: XC115F ALPHA | B14: 22 | C14: 9 | D14: 19 | E14: 20 | F14: 25 | G14: 24 | H14: 20 | I14: 13 | J14: 10 | K14: 8 | L14: 34 | M14: 19 | N14: =B14+C14+D14+E14+F14+G14+H14+I14+J14+K14+L14+M14 -> 223
A15: XC115B RAY ZR(Drum) | B15: 1055 | C15: 1595 | D15: 1296 | E15: 1444 | F15: 1341 | G15: 1225 | H15: 1602 | I15: 1635 | J15: 1375 | K15: 1542 | L15: 1455 | M15: 1509 | N15: =B15+C15+D15+E15+F15+G15+H15+I15+J15+K15+L15+M15 -> 17074
A16: XC115BD RAY ZR(Disk) | B16: 218 | C16: 185 | D16: 176 | E16: 300 | F16: 431 | G16: 523 | H16: 462 | I16: 571 | J16: 1047 | K16: 1141 | L16: 874 | M16: 1243 | N16: =B16+C16+D16+E16+F16+G16+H16+I16+J16+K16+L16+M16 -> 7171

Sheet 2016
B1: JAN | C1: FEB | D1: MAR | E1: APR | F1: MAY | G1: JUN | H1: JUL | I1: AUG | J1: SEP | K1: OCT | L1: NOV | M1: DEC | N1: Total
A2: FZ16 | D2: 1 | F2: 1 | H2: 1 | I2: 1 | N2: =B2+C2+D2+E2+F2+G2+H2+I2+J2+K2+L2+M2 -> 4
A3: FZ16S | E3: 1 | F3: 1 | H3: 1 | I3: 1 | N3: =B3+C3+D3+E3+F3+G3+H3+I3+J3+K3+L3+M3 -> 4
A4: FZ16ST(FAZER) | E4: 1 | F4: 2 | N4: =B4+C4+D4+E4+F4+G4+H4+I4+J4+K4+L4+M4 -> 3
A5: FZ合計 | B5: =SUM(B2:B4) -> 0 | C5: =SUM(C2:C4) -> 0 | D5: =SUM(D2:D4) -> 1 | E5: =SUM(E2:E4) -> 2 | F5: =SUM(F2:F4) -> 4 | G5: =SUM(G2:G4) -> 0 | H5: =SUM(H2:H4) -> 2 | I5: =SUM(I2:I4) -> 2 | ... M5: =SUM(M2:M4) -> 0 | N5: =B5+C5+D5+E5+F5+G5+H5+I5+J5+K5+L5+M5 -> 11
A6: FZN150 | B6: 229 | C6: 244 | D6: 339 | E6: 602 | F6: 478 | G6: 322 | H6: 182 | I6: 187 | J6: 129 | K6: 335 | L6: 356 | M6: 358 | N6: =B6+C6+D6+E6+F6+G6+H6+I6+J6+K6+L6+M6 -> 3761
A7: FZN150D | B7: 338 | C7: 326 | D7: 437 | E7: 565 | F7: 501 | G7: 669 | H7: 758 | I7: 754 | J7: 662 | K7: 605 | L7: 654 | M7: 926 | N7: =B7+C7+D7+E7+F7+G7+H7+I7+J7+K7+L7+M7 -> 7195
A8: FZH150(FAZER) | B8: 43 | C8: 51 | D8: 66 | E8: 88 | F8: 73 | G8: 72 | H8: 73 | I8: 71 | J8: 33 | K8: 58 | L8: 72 | M8: 90 | N8: =B8+C8+D8+E8+F8+G8+H8+I8+J8+K8+L8+M8 -> 790
A9: FZ合計 | B9: =SUM(B6:B8) -> 610 | C9: =SUM(C6:C8) -> 621 | D9: =SUM(D6:D8) -> 842 | E9: =SUM(E6:E8) -> 1255 | F9: =SUM(F6:F8) -> 1052 | G9: =SUM(G6:G8) -> 1063 | H9: =SUM(H6:H8) -> 1013 | I9: =SUM(I6:I8) -> 1012 | ... N9: =SUM(N6:N8) -> 11746
A10: YZF-R15 | B10: 2 | C10: 5 | D10: 9 | E10: 8 | F10: 5 | G10: 9 | H10: 10 | I10: 7 | J10: 8 | K10: 10 | L10: 2 | M10: 5 | N10: =B10+C10+D10+E10+F10+G10+H10+I10+J10+K10+L10+M10 -> 80
A11: YC125-5 | B11: 83 | C11: 66 | D11: 93 | E11: 118 | F11: 98 | G11: 115 | H11: 98 | I11: 98 | J11: 71 | K11: 70 | L11: 56 | M11: 70 | N11: =B11+C11+D11+E11+F11+G11+H11+I11+J11+K11+L11+M11 -> 1036
A12: RAY Original | D12: 6 | E12: 3 | F12: 3 | G12: 5 | H12: 3 | I12: 1 | N12: =B12+C12+D12+E12+F12+G12+H12+I12+J12+K12+L12+M12 -> 21
A13: XC115B | B13: 428 | C13: 367 | D13: 459 | E13: 514 | F13: 547 | G13: 429 | H13: 263 | I13: 99 | J13: 55 | K13: 47 | L13: 25 | M13: 17 | N13: =B13+C13+D13+E13+F13+G13+H13+I13+J13+K13+L13+M13 -> 3250
A14: FASCINO | D14: 5 | E14: 68 | F14: 82 | G14: 88 | H14: 89 | I14: 69 | J14: 93 | K14: 71 | L14: 71 | M14: 66 | N14: =B14+C14+D14+E14+F14+G14+H14+I14+J14+K14+L14+M14 -> 702
A15: RAY | B15: 2 | C15: 3 | N15: =B15+C15+D15+E15+F15+G15+H15+I15+J15+K15+L15+M15 -> 5
A16: XC115F | B16: 100 | C16: 63 | D16: 97 | E16: 93 | F16: 122 | G16: 92 | H16: 73 | I16: 31 | J16: 50 | K16: 39 | L16: 44 | M16: 53 | N16: =B16+C16+D16+E16+F16+G16+H16+I16+J16+K16+L16+M16 -> 857
A17: RAY ZR(Drum) | H17: 290 | I17: 1144 | J17: 887 | K17: 999 | L17: 1047 | M17: 1231 | N17: =B17+C17+D17+E17+F17+G17+H17+I17+J17+K17+L17+M17 -> 5598
A18: RAY ZR(Disk) | L18: 226 | M18: 281 | N18: =B18+C18+D18+E18+F18+G18+H18+I18+J18+K18+L18+M18 -> 507

Sheet 2015
B1: JAN | C1: FEB | D1: MAR | E1: APR | F1: MAY | G1: JUN | H1: JUL | I1: AUG | J1: SEP | K1: OCT | L1: NOV | M1: DEC | N1: Total
A2: FZ16 | B2: 228 | C2: 262 | D2: 387 | E2: 408 | F2: 152 | G2: 52 | H2: 11 | I2: 1 | J2: 1 | K2: 2 | M2: 1 | N2: =B2+C2+D2+E2+F2+G2+H2+I2+J2+K2+L2+M2 -> 1505
A3: FZ16S | B3: 258 | C3: 305 | D3: 346 | E3: 376 | F3: 158 | G3: 68 | H3: 25 | I3: 9 | J3: 6 | K3: 3 | L3: 3 | N3: =B3+C3+D3+E3+F3+G3+H3+I3+J3+K3+L3+M3 -> 1557
A4: FZ16ST(FAZER) | B4: 37 | C4: 51 | D4: 55 | E4: 30 | F4: 12 | G4: 6 | H4: 2 | I4: 1 | K4: 1 | N4: =B4+C4+D4+E4+F4+G4+H4+I4+J4+K4+L4+M4 -> 195
A5: FZ合計 | B5: =SUM(B2:B4) -> 523 | C5: =SUM(C2:C4) -> 618 | D5: =SUM(D2:D4) -> 788 | E5: =SUM(E2:E4) -> 814 | F5: =SUM(F2:F4) -> 322 | G5: =SUM(G2:G4) -> 126 | H5: =SUM(H2:H4) -> 38 | I5: =SUM(I2:I4) -> 11 | ... M5: =SUM(M2:M4) -> 1 | N5: =B5+C5+D5+E5+F5+G5+H5+I5+J5+K5+L5+M5 -> 3257
A6: FZN150 | F6: 62 | G6: 175 | H6: 449 | I6: 344 | J6: 382 | K6: 176 | L6: 260 | M6: 305 | N6: =B6+C6+D6+E6+F6+G6+H6+I6+J6+K6+L6+M6 -> 2153
A7: FZN150D | F7: 77 | G7: 291 | H7: 582 | I7: 607 | J7: 750 | K7: 551 | L7: 514 | M7: 570 | N7: =B7+C7+D7+E7+F7+G7+H7+I7+J7+K7+L7+M7 -> 3942
A8: FZH150(FAZER) | G8: 10 | H8: 63 | I8: 81 | J8: 81 | K8: 51 | L8: 58 | M8: 66 | N8: =B8+C8+D8+E8+F8+G8+H8+I8+J8+K8+L8+M8 -> 410
A9: FZ合計 | F9: =SUM(F6:F8) -> 139 | G9: =SUM(G6:G8) -> 476 | H9: =SUM(H6:H8) -> 1094 | I9: =SUM(I6:I8) -> 1032 | J9: =SUM(J6:J8) -> 1213 | K9: =SUM(K6:K8) -> 778 | L9: =SUM(L6:L8) -> 832 | M9: =SUM(M6:M8) -> 941 | N9: =B9+C9+D9+E9+F9+G9+H9+I9+J9+K9+L9+M9 -> 6505
A10: YZF-R15 | D10: 1 | E10: 3 | F10: 4 | G10: 6 | H10: 1 | I10: 0 | J10: 3 | K10: 1 | L10: 6 | M10: 7 | N10: =B10+C10+D10+E10+F10+G10+H10+I10+J10+K10+L10+M10 -> 32
A11: SZ X | B11: 1 | C11: 1 | E11: 1 | N11: =M11+B11+C11+D11+E11+F11+G11+H11+I11+J11+K11+L11 -> 3
A12: SZ R | E12: 1 | N12: =M12+B12+C12+D12+E12+F12+G12+H12+I12+J12+K12+L12 -> 1
A13: YC125-5 | M13: 115 | N13: =B13+C13+D13+E13+F13+G13+H13+I13+J13+K13+L13+M13 -> 115
A14: XTZ 125E | B14: 1 | E14: 1 | N14: =M14+B14+C14+D14+E14+F14+G14+H14+I14+J14+K14+L14 -> 2
A15: YBR110 | B15: 6 | C15: 2 | D15: 2 | F15: 26 | G15: 1 | H15: 7 | I15: 1 | J15: 2 | K15: 1 | L15: 1 | M15: 2 | N15: =B15+C15+D15+E15+F15+G15+H15+I15+J15+K15+L15+M15 -> 51
A16: RAY Original | B16: 205 | C16: 282 | D16: 328 | E16: 239 | F16: 156 | G16: 144 | H16: 85 | I16: 28 | J16: 15 | K16: 3 | L16: 20 | M16: 10 | N16: =B16+C16+D16+E16+F16+G16+H16+I16+J16+K16+L16+M16 -> 1515
A17: XC115B | D17: 70 | E17: 341 | F17: 315 | G17: 219 | H17: 112 | I17: 314 | J17: 867 | K17: 589 | L17: 551 | M17: 587 | N17: =B17+C17+D17+E17+F17+G17+H17+I17+J17+K17+L17+M17 -> 3965
A18: XC115F | B18: 67 | C18: 119 | D18: 135 | E18: 144 | F18: 150 | G18: 108 | H18: 167 | I18: 129 | J18: 164 | K18: 130 | L18: 95 | M18: 151 | N18: =B18+C18+D18+E18+F18+G18+H18+I18+J18+K18+L18+M18 -> 1559

Sheet 2014
B1: JAN | C1: FEB | D1: MAR | E1: APR | F1: May | G1: Jun | H1: Jul | I1: Aug | J1: Sep | K1: Oct | L1: Nov | M1: Dec | N1: Total
A2: YZ 250 | I2: 1 | N2: =B2+C2+D2+E2+F2+G2+H2+I2+J2+K2+L2+M2 -> 1
A3: FZ16 | B3: 140 | C3: 122 | D3: 122 | E3: 150 | F3: 172 | G3: 201 | H3: 241 | I3: 241 | J3: 282 | K3: 214 | L3: 189 | M3: 239 | N3: =B3+C3+D3+E3+F3+G3+H3+I3+J3+K3+L3+M3 -> 2313
A4: FZ16S | B4: 149 | C4: 166 | D4: 196 | E4: 181 | F4: 205 | G4: 187 | H4: 261 | I4: 258 | J4: 237 | K4: 272 | L4: 208 | M4: 249 | N4: =B4+C4+D4+E4+F4+G4+H4+I4+J4+K4+L4+M4 -> 2569
A5: FZ16ST(FAZER) | B5: 21 | C5: 18 | D5: 30 | E5: 26 | F5: 29 | G5: 29 | H5: 15 | I5: 21 | J5: 22 | K5: 35 | L5: 34 | M5: 33 | N5: =B5+C5+D5+E5+F5+G5+H5+I5+J5+K5+L5+M5 -> 313
A6: FZ合計 | B6: =SUM(B3:B5) -> 310 | C6: =SUM(C3:C5) -> 306 | D6: =SUM(D3:D5) -> 348 | E6: =SUM(E3:E5) -> 357 | F6: =SUM(F3:F5) -> 406 | G6: =SUM(G3:G5) -> 417 | H6: =SUM(H3:H5) -> 517 | I6: =SUM(I3:I5) -> 520 | ... N6: =SUM(N3:N5) -> 5195
A7: YZF-R15 | B7: 0 | C7: 0 | D7: 0 | E7: 0 | F7: 0 | G7: 0 | H7: 0 | I7: 2 | J7: 1 | K7: 2 | L7: 0 | M7: 0 | N7: =B7+C7+D7+E7+F7+G7+H7+I7+J7+K7+L7+M7 -> 5
A8: SZ X | B8: 16 | C8: 43 | D8: 42 | E8: 53 | F8: 32 | G8: 33 | H8: 25 | I8: 25 | J8: 27 | K8: 15 | L8: 8 | M8: 3 | N8: =M8+B8+C8+D8+E8+F8+G8+H8+I8+J8+K8+L8 -> 322
A9: SZ R | B9: 24 | C9: 32 | D9: 19 | E9: 8 | F9: 4 | G9: 3 | H9: 10 | I9: 1 | J9: 3 | K9: 1 | N9: =M9+B9+C9+D9+E9+F9+G9+H9+I9+J9+K9+L9 -> 105
A10: XTZ 125E | D10: 2 | F10: 1 | G10: 1 | I10: 1 | N10: =M10+B10+C10+D10+E10+F10+G10+H10+I10+J10+K10+L10 -> 5
A11: YZ 125 | I11: 2 | J11: 1 | N11: =M11+B11+C11+D11+E11+F11+G11+H11+I11+J11+K11+L11 -> 3
A12: YBR110 | B12: 0 | D12: 0 | E12: 0 | F12: 0 | G12: 0 | H12: 0 | I12: 0 | J12: 0 | K12: 0 | L12: 0 | M12: 3 | N12: =B12+C12+D12+E12+F12+G12+H12+I12+J12+K12+L12+M12 -> 3
A13: RAY Original | B13: 259 | C13: 277 | D13: 330 | E13: 291 | F13: 284 | G13: 252 | H13: 225 | I13: 242 | J13: 271 | K13: 312 | L13: 269 | M13: 279 | N13: =B13+C13+D13+E13+F13+G13+H13+I13+J13+K13+L13+M13 -> 3291
A14: XC115F | M14: 55 | N14: =B14+C14+D14+E14+F14+G14+H14+I14+J14+K14+L14+M14 -> 55

Sheet 2013
B1: JAN | C1: FEB | D1: MAR | E1: APR | F1: MAY | G1: JUN | H1: JUL | I1: AUG | J1: SEP | K1: OCT | L1: NOV | M1: DEC | N1: Total
A2: FZ16 | B2: 79 | C2: 61 | D2: 93 | E2: 59 | F2: 49 | G2: 29 | H2: 69 | I2: 84 | J2: 83 | K2: 95 | L2: 105 | M2: 129 | N2: =M2+B2+C2+D2+E2+F2+G2+H2+I2+J2+K2+L2 -> 935
A3: FZ16S | B3: 78 | C3: 54 | D3: 64 | E3: 35 | F3: 31 | G3: 36 | H3: 66 | I3: 142 | J3: 97 | K3: 96 | L3: 106 | M3: 177 | N3: =M3+B3+C3+D3+E3+F3+G3+H3+I3+J3+K3+L3 -> 982
A4: FZ16ST(FAZER) | B4: 12 | C4: 4 | D4: 12 | E4: 4 | F4: 6 | G4: 7 | H4: 8 | I4: 24 | J4: 16 | K4: 20 | L4: 15 | M4: 16 | N4: =M4+B4+C4+D4+E4+F4+G4+H4+I4+J4+K4+L4 -> 144
A5: FZ合計 | B5: =SUM(B2:B4) -> 169 | C5: =SUM(C2:C4) -> 119 | D5: =SUM(D2:D4) -> 169 | E5: =SUM(E2:E4) -> 98 | F5: =SUM(F2:F4) -> 86 | G5: =SUM(G2:G4) -> 72 | H5: =SUM(H2:H4) -> 143 | I5: =SUM(I2:I4) -> 250 | ... N5: =SUM(N2:N4) -> 2061
A6: SZ 16 | B6: 4 | E6: 1 | F6: 1 | G6: 3 | N6: =M6+B6+C6+D6+E6+F6+G6+H6+I6+J6+K6+L6 -> 9
A7: SZ X | B7: 7 | D7: 3 | E7: 3 | F7: 2 | G7: 3 | H7: 1 | I7: 3 | J7: 2 | K7: 5 | L7: 6 | M7: 40 | N7: =M7+B7+C7+D7+E7+F7+G7+H7+I7+J7+K7+L7 -> 75
A8: SZ R | B8: 3 | C8: 3 | D8: 3 | E8: 7 | F8: 15 | G8: 14 | H8: 10 | I8: 12 | J8: 7 | K8: 14 | L8: 25 | M8: 55 | N8: =M8+B8+C8+D8+E8+F8+G8+H8+I8+J8+K8+L8 -> 168
A9: XTZ 125E | J9: 1 | L9: 1 | N9: =M9+B9+C9+D9+E9+F9+G9+H9+I9+J9+K9+L9 -> 2
A10: YZ 125 | G10: 25 | N10: =M10+B10+C10+D10+E10+F10+G10+H10+I10+J10+K10+L10 -> 25
A11: YBR125 | B11: 2 | C11: 0 | D11: 0 | E11: 0 | F11: 0 | H11: 0 | I11: 0 | J11: 0 | N11: =SUM(B11:M11) -> 2
A12: RAY Original | E12: 145 | F12: 182 | G12: 119 | H12: 192 | I12: 206 | J12: 182 | K12: 226 | L12: 243 | M12: 246 | N12: =M12+B12+C12+D12+E12+F12+G12+H12+I12+J12+K12+L12 -> 1741
